Workbook

Sheet Tahliliy qism
C2: O'ZBEKISTON RESPUBLIKASI VA VILOYATLAR KESIMIDA IQTISODIY VA IJTIMOIY INDEKSLARNING UMUMIY TAHLILI
C9: 1. O'ZBEKISTON RESPUBLIKASI VA VILOYATLAR KESIMIDA YILLIK YALPI ICHKI MAHSULOT HAJMINING O'SISH SURATI
C13: Yillar | D13: O'zbekiston | E13: Qoraqalpog'iston | F13: Andijon | G13: Buxoro | H13: Jizzax | I13: Qashqadaryo | J13: Navoiy | K13: Namangan | L13: Samarqand | M13: Surxondaryo | N13: Sirdaryo | O13: Toshkent vil | P13: Farg'ona | Q13: Xorazm | R13: Toshkent sh
C14: 2011 | D14: ='Ozbekiston Respublikasi'!C3/'Ozbekiston Respublikasi'!C2-1 -> 0.31242509 | E14: ='Qoraqalpogiston Respublikasi'!C3/'Qoraqalpogiston Respublikasi'!C2-1 -> 0.29993856 | F14: ='Andijon Viloyati'!C3/'Andijon Viloyati'!C2-1 -> 0.36243773 | G14: ='Buxoro Viloyati'!C3/'Buxoro Viloyati'!C2-1 -> 0.3206992 | H14: ='Jizzah Viloyati'!C3/'Jizzah Viloyati'!C2-1 -> 0.37317103 | I14: ='Qashqadaryo Viloyati'!C3/'Qashqadaryo Viloyati'!C2-1 -> 0.28576298 | J14: ='Navoiy Viloyati'!C3/'Navoiy Viloyati'!C2-1 -> 0.22555505 | K14: ='Namangan Viloyati'!C3/'Namangan Viloyati'!C2-1 -> 0.37817815 | L14: ='Samarqand Viloyati'!C3/'Samarqand Viloyati'!C2-1 -> 0.26064619 | M14: ='Surxandaryo Viloyati'!C3/'Surxandaryo Viloyati'!C2-1 -> 0.51993583 | N14: ='Sirdaryo Viloyati'!C3/'Sirdaryo Viloyati'!C2-1 -> 0.40422209 | O14: ='Toshkent Viloyati '!C3/'Toshkent Viloyati '!C2-1 -> 0.33804943 | P14: ='Fargona Viloyati'!C3/'Fargona Viloyati'!C2-1 -> 0.34077843 | Q14: ='Xorazm Viloyati'!C3/'Xorazm Viloyati'!C2-1 -> 0.3479512 | R14: ='Toshkent shahri'!C3/'Toshkent shahri'!C2-1 -> 0.29351473
C15: 2012 | D15: ='Ozbekiston Respublikasi'!C4/'Ozbekiston Respublikasi'!C3-1 -> 0.2309583 | E15: ='Qoraqalpogiston Respublikasi'!C4/'Qoraqalpogiston Respublikasi'!C3-1 -> 0.25135143 | F15: ='Andijon Viloyati'!C4/'Andijon Viloyati'!C3-1 -> 0.23141767 | G15: ='Buxoro Viloyati'!C4/'Buxoro Viloyati'!C3-1 -> 0.17295973 | H15: ='Jizzah Viloyati'!C4/'Jizzah Viloyati'!C3-1 -> 0.23280802 | I15: ='Qashqadaryo Viloyati'!C4/'Qashqadaryo Viloyati'!C3-1 -> 0.22774781 | J15: ='Navoiy Viloyati'!C4/'Navoiy Viloyati'!C3-1 -> 0.23404407 | K15: ='Namangan Viloyati'!C4/'Namangan Viloyati'!C3-1 -> 0.24988573 | L15: ='Samarqand Viloyati'!C4/'Samarqand Viloyati'!C3-1 -> 0.21638369 | M15: ='Surxandaryo Viloyati'!C4/'Surxandaryo Viloyati'!C3-1 -> 0.2345694 | N15: ='Sirdaryo Viloyati'!C4/'Sirdaryo Viloyati'!C3-1 -> 0.22880153 | O15: ='Toshkent Viloyati '!C4/'Toshkent Viloyati '!C3-1 -> 0.24994852 | P15: ='Fargona Viloyati'!C4/'Fargona Viloyati'!C3-1 -> 0.25124608 | Q15: ='Xorazm Viloyati'!C4/'Xorazm Viloyati'!C3-1 -> 0.23546201 | R15: ='Toshkent shahri'!C4/'Toshkent shahri'!C3-1 -> 0.23950867
C16: 2013 | D16: ='Ozbekiston Respublikasi'!C5/'Ozbekiston Respublikasi'!C4-1 -> 0.21687522 | E16: ='Qoraqalpogiston Respublikasi'!C5/'Qoraqalpogiston Respublikasi'!C4-1 -> 0.30291299 | F16: ='Andijon Viloyati'!C5/'Andijon Viloyati'!C4-1 -> 0.31489402 | G16: ='Buxoro Viloyati'!C5/'Buxoro Viloyati'!C4-1 -> 0.19269136 | H16: ='Jizzah Viloyati'!C5/'Jizzah Viloyati'!C4-1 -> 0.22036607 | I16: ='Qashqadaryo Viloyati'!C5/'Qashqadaryo Viloyati'!C4-1 -> 0.17324175 | J16: ='Navoiy Viloyati'!C5/'Navoiy Viloyati'!C4-1 -> 0.18959843 | K16: ='Namangan Viloyati'!C5/'Namangan Viloyati'!C4-1 -> 0.23344061 | L16: ='Samarqand Viloyati'!C5/'Samarqand Viloyati'!C4-1 -> 0.24992012 | M16: ='Surxandaryo Viloyati'!C5/'Surxandaryo Viloyati'!C4-1 -> 0.17577473 | N16: ='Sirdaryo Viloyati'!C5/'Sirdaryo Viloyati'!C4-1 -> 0.18563715 | O16: ='Toshkent Viloyati '!C5/'Toshkent Viloyati '!C4-1 -> 0.22519483 | P16: ='Fargona Viloyati'!C5/'Fargona Viloyati'!C4-1 -> 0.22324822 | Q16: ='Xorazm Viloyati'!C5/'Xorazm Viloyati'!C4-1 -> 0.23185139 | R16: ='Toshkent shahri'!C5/'Toshkent shahri'!C4-1 -> 0.21231238
C17: 2014 | D17: ='Ozbekiston Respublikasi'!C6/'Ozbekiston Respublikasi'!C5-1 -> 0.21822444 | E17: ='Qoraqalpogiston Respublikasi'!C6/'Qoraqalpogiston Respublikasi'!C5-1 -> 0.24781679 | F17: ='Andijon Viloyati'!C6/'Andijon Viloyati'!C5-1 -> 0.1945806 | G17: ='Buxoro Viloyati'!C6/'Buxoro Viloyati'!C5-1 -> 0.23710884 | H17: ='Jizzah Viloyati'!C6/'Jizzah Viloyati'!C5-1 -> 0.24614133 | I17: ='Qashqadaryo Viloyati'!C6/'Qashqadaryo Viloyati'!C5-1 -> 0.19764553 | J17: ='Navoiy Viloyati'!C6/'Navoiy Viloyati'!C5-1 -> 0.19456882 | K17: ='Namangan Viloyati'!C6/'Namangan Viloyati'!C5-1 -> 0.22952395 | L17: ='Samarqand Viloyati'!C6/'Samarqand Viloyati'!C5-1 -> 0.25036702 | M17: ='Surxandaryo Viloyati'!C6/'Surxandaryo Viloyati'!C5-1 -> 0.24127408 | N17: ='Sirdaryo Viloyati'!C6/'Sirdaryo Viloyati'!C5-1 -> 0.20537524 | O17: ='Toshkent Viloyati '!C6/'Toshkent Viloyati '!C5-1 -> 0.21748408 | P17: ='Fargona Viloyati'!C6/'Fargona Viloyati'!C5-1 -> 0.24065036 | Q17: ='Xorazm Viloyati'!C6/'Xorazm Viloyati'!C5-1 -> 0.24697721 | R17: ='Toshkent shahri'!C6/'Toshkent shahri'!C5-1 -> 0.22700347
C18: 2015 | D18: ='Ozbekiston Respublikasi'!C7/'Ozbekiston Respublikasi'!C6-1 -> 0.18742473 | E18: ='Qoraqalpogiston Respublikasi'!C7/'Qoraqalpogiston Respublikasi'!C6-1 -> 0.21092752 | F18: ='Andijon Viloyati'!C7/'Andijon Viloyati'!C6-1 -> 0.17807582 | G18: ='Buxoro Viloyati'!C7/'Buxoro Viloyati'!C6-1 -> 0.2126281 | H18: ='Jizzah Viloyati'!C7/'Jizzah Viloyati'!C6-1 -> 0.18741343 | I18: ='Qashqadaryo Viloyati'!C7/'Qashqadaryo Viloyati'!C6-1 -> 0.19519692 | J18: ='Navoiy Viloyati'!C7/'Navoiy Viloyati'!C6-1 -> 0.13679303 | K18: ='Namangan Viloyati'!C7/'Namangan Viloyati'!C6-1 -> 0.21220978 | L18: ='Samarqand Viloyati'!C7/'Samarqand Viloyati'!C6-1 -> 0.19640875 | M18: ='Surxandaryo Viloyati'!C7/'Surxandaryo Viloyati'!C6-1 -> 0.20784035 | N18: ='Sirdaryo Viloyati'!C7/'Sirdaryo Viloyati'!C6-1 -> 0.22908432 | O18: ='Toshkent Viloyati '!C7/'Toshkent Viloyati '!C6-1 -> 0.17339986 | P18: ='Fargona Viloyati'!C7/'Fargona Viloyati'!C6-1 -> 0.20099174 | Q18: ='Xorazm Viloyati'!C7/'Xorazm Viloyati'!C6-1 -> 0.21920203 | R18: ='Toshkent shahri'!C7/'Toshkent shahri'!C6-1 -> 0.20446585
C19: 2016 | D19: ='Ozbekiston Respublikasi'!C8/'Ozbekiston Respublikasi'!C7-1 -> 0.15833029 | E19: ='Qoraqalpogiston Respublikasi'!C8/'Qoraqalpogiston Respublikasi'!C7-1 -> 0.26194559 | F19: ='Andijon Viloyati'!C8/'Andijon Viloyati'!C7-1 -> 0.17008163 | G19: ='Buxoro Viloyati'!C8/'Buxoro Viloyati'!C7-1 -> 0.16673229 | H19: ='Jizzah Viloyati'!C8/'Jizzah Viloyati'!C7-1 -> 0.16905544 | I19: ='Qashqadaryo Viloyati'!C8/'Qashqadaryo Viloyati'!C7-1 -> 0.17421256 | J19: ='Navoiy Viloyati'!C8/'Navoiy Viloyati'!C7-1 -> 0.13830139 | K19: ='Namangan Viloyati'!C8/'Namangan Viloyati'!C7-1 -> 0.19853427 | L19: ='Samarqand Viloyati'!C8/'Samarqand Viloyati'!C7-1 -> 0.24158033 | M19: ='Surxandaryo Viloyati'!C8/'Surxandaryo Viloyati'!C7-1 -> 0.10349845 | N19: ='Sirdaryo Viloyati'!C8/'Sirdaryo Viloyati'!C7-1 -> 0.20859615 | O19: ='Toshkent Viloyati '!C8/'Toshkent Viloyati '!C7-1 -> 0.093653957 | P19: ='Fargona Viloyati'!C8/'Fargona Viloyati'!C7-1 -> 0.11681869 | Q19: ='Xorazm Viloyati'!C8/'Xorazm Viloyati'!C7-1 -> 0.16023468 | R19: ='Toshkent shahri'!C8/'Toshkent shahri'!C7-1 -> 0.24142606
C20: 2017 | D20: ='Ozbekiston Respublikasi'!C9/'Ozbekiston Respublikasi'!C8-1 -> 0.27358971 | E20: ='Qoraqalpogiston Respublikasi'!C9/'Qoraqalpogiston Respublikasi'!C8-1 -> 0.30700746 | F20: ='Andijon Viloyati'!C9/'Andijon Viloyati'!C8-1 -> 0.24637855 | G20: ='Buxoro Viloyati'!C9/'Buxoro Viloyati'!C8-1 -> 0.20341792 | H20: ='Jizzah Viloyati'!C9/'Jizzah Viloyati'!C8-1 -> 0.24930614 | I20: ='Qashqadaryo Viloyati'!C9/'Qashqadaryo Viloyati'!C8-1 -> 0.088643581 | J20: ='Navoiy Viloyati'!C9/'Navoiy Viloyati'!C8-1 -> 0.44876092 | K20: ='Namangan Viloyati'!C9/'Namangan Viloyati'!C8-1 -> 0.23551829 | L20: ='Samarqand Viloyati'!C9/'Samarqand Viloyati'!C8-1 -> 0.21661594 | M20: ='Surxandaryo Viloyati'!C9/'Surxandaryo Viloyati'!C8-1 -> 0.247271 | N20: ='Sirdaryo Viloyati'!C9/'Sirdaryo Viloyati'!C8-1 -> 0.19313153 | O20: ='Toshkent Viloyati '!C9/'Toshkent Viloyati '!C8-1 -> 0.25800211 | P20: ='Fargona Viloyati'!C9/'Fargona Viloyati'!C8-1 -> 0.18586195 | Q20: ='Xorazm Viloyati'!C9/'Xorazm Viloyati'!C8-1 -> 0.17110825 | R20: ='Toshkent shahri'!C9/'Toshkent shahri'!C8-1 -> 0.36405107
C21: 2018 | D21: ='Ozbekiston Respublikasi'!C10/'Ozbekiston Respublikasi'!C9-1 -> 0.33873827 | E21: ='Qoraqalpogiston Respublikasi'!C10/'Qoraqalpogiston Respublikasi'!C9-1 -> 0.40832097 | F21: ='Andijon Viloyati'!C10/'Andijon Viloyati'!C9-1 -> 0.38067254 | G21: ='Buxoro Viloyati'!C10/'Buxoro Viloyati'!C9-1 -> 0.29057715 | H21: ='Jizzah Viloyati'!C10/'Jizzah Viloyati'!C9-1 -> 0.35037455 | I21: ='Qashqadaryo Viloyati'!C10/'Qashqadaryo Viloyati'!C9-1 -> 0.22602435 | J21: ='Navoiy Viloyati'!C10/'Navoiy Viloyati'!C9-1 -> 0.47323935 | K21: ='Namangan Viloyati'!C10/'Namangan Viloyati'!C9-1 -> 0.233585 | L21: ='Samarqand Viloyati'!C10/'Samarqand Viloyati'!C9-1 -> 0.22347059 | M21: ='Surxandaryo Viloyati'!C10/'Surxandaryo Viloyati'!C9-1 -> 0.24876809 | N21: ='Sirdaryo Viloyati'!C10/'Sirdaryo Viloyati'!C9-1 -> 0.23125262 | O21: ='Toshkent Viloyati '!C10/'Toshkent Viloyati '!C9-1 -> 0.36186275 | P21: ='Fargona Viloyati'!C10/'Fargona Viloyati'!C9-1 -> 0.31370561 | Q21: ='Xorazm Viloyati'!C10/'Xorazm Viloyati'!C9-1 -> 0.34218568 | R21: ='Toshkent shahri'!C10/'Toshkent shahri'!C9-1 -> 0.30088719
C22: 2019 | D22: ='Ozbekiston Respublikasi'!C11/'Ozbekiston Respublikasi'!C10-1 -> 0.25316219 | E22: ='Qoraqalpogiston Respublikasi'!C11/'Qoraqalpogiston Respublikasi'!C10-1 -> 0.23354997 | F22: ='Andijon Viloyati'!C11/'Andijon Viloyati'!C10-1 -> 0.25425953 | G22: ='Buxoro Viloyati'!C11/'Buxoro Viloyati'!C10-1 -> 0.28353819 | H22: ='Jizzah Viloyati'!C11/'Jizzah Viloyati'!C10-1 -> 0.26125942 | I22: ='Qashqadaryo Viloyati'!C11/'Qashqadaryo Viloyati'!C10-1 -> 0.23101002 | J22: ='Navoiy Viloyati'!C11/'Navoiy Viloyati'!C10-1 -> 0.55937757 | K22: ='Namangan Viloyati'!C11/'Namangan Viloyati'!C10-1 -> 0.28000906 | L22: ='Samarqand Viloyati'!C11/'Samarqand Viloyati'!C10-1 -> 0.18982566 | M22: ='Surxandaryo Viloyati'!C11/'Surxandaryo Viloyati'!C10-1 -> 0.21383368 | N22: ='Sirdaryo Viloyati'!C11/'Sirdaryo Viloyati'!C10-1 -> 0.39159978 | O22: ='Toshkent Viloyati '!C11/'Toshkent Viloyati '!C10-1 -> 0.36236639 | P22: ='Fargona Viloyati'!C11/'Fargona Viloyati'!C10-1 -> 0.21703716 | Q22: ='Xorazm Viloyati'!C11/'Xorazm Viloyati'!C10-1 -> 0.22429362 | R22: ='Toshkent shahri'!C11/'Toshkent shahri'!C10-1 -> 0.32398614
C23: 2020 | D23: ='Ozbekiston Respublikasi'!C12/'Ozbekiston Respublikasi'!C11-1 -> 0.13706757 | E23: ='Qoraqalpogiston Respublikasi'!C12/'Qoraqalpogiston Respublikasi'!C11-1 -> 0.093732607 | F23: ='Andijon Viloyati'!C12/'Andijon Viloyati'!C11-1 -> 0.11179492 | G23: ='Buxoro Viloyati'!C12/'Buxoro Viloyati'!C11-1 -> 0.10701482 | H23: ='Jizzah Viloyati'!C12/'Jizzah Viloyati'!C11-1 -> 0.1249717 | I23: ='Qashqadaryo Viloyati'!C12/'Qashqadaryo Viloyati'!C11-1 -> 0.084268108 | J23: ='Navoiy Viloyati'!C12/'Navoiy Viloyati'!C11-1 -> 0.4227891 | K23: ='Namangan Viloyati'!C12/'Namangan Viloyati'!C11-1 -> 0.1628313 | L23: ='Samarqand Viloyati'!C12/'Samarqand Viloyati'!C11-1 -> 0.10210403 | M23: ='Surxandaryo Viloyati'!C12/'Surxandaryo Viloyati'!C11-1 -> 0.08744169 | N23: ='Sirdaryo Viloyati'!C12/'Sirdaryo Viloyati'!C11-1 -> 0.055452081 | O23: ='Toshkent Viloyati '!C12/'Toshkent Viloyati '!C11-1 -> 0.19735665 | P23: ='Fargona Viloyati'!C12/'Fargona Viloyati'!C11-1 -> 0.13543742 | Q23: ='Xorazm Viloyati'!C12/'Xorazm Viloyati'!C11-1 -> 0.1080502 | R23: ='Toshkent shahri'!C12/'Toshkent shahri'!C11-1 -> 0.12141288
C24: 2021 | D24: ='Ozbekiston Respublikasi'!C13/'Ozbekiston Respublikasi'!C12-1 -> 0.22138633 | E24: ='Qoraqalpogiston Respublikasi'!C13/'Qoraqalpogiston Respublikasi'!C12-1 -> 0.17451007 | F24: ='Andijon Viloyati'!C13/'Andijon Viloyati'!C12-1 -> 0.1523746 | G24: ='Buxoro Viloyati'!C13/'Buxoro Viloyati'!C12-1 -> 0.21863053 | H24: ='Jizzah Viloyati'!C13/'Jizzah Viloyati'!C12-1 -> 0.26193488 | I24: ='Qashqadaryo Viloyati'!C13/'Qashqadaryo Viloyati'!C12-1 -> 0.20999513 | J24: ='Navoiy Viloyati'!C13/'Navoiy Viloyati'!C12-1 -> 0.14646656 | K24: ='Namangan Viloyati'!C13/'Namangan Viloyati'!C12-1 -> 0.22899345 | L24: ='Samarqand Viloyati'!C13/'Samarqand Viloyati'!C12-1 -> 0.24102313 | M24: ='Surxandaryo Viloyati'!C13/'Surxandaryo Viloyati'!C12-1 -> 0.21590336 | N24: ='Sirdaryo Viloyati'!C13/'Sirdaryo Viloyati'!C12-1 -> 0.17997111 | O24: ='Toshkent Viloyati '!C13/'Toshkent Viloyati '!C12-1 -> 0.26756296 | P24: ='Fargona Viloyati'!C13/'Fargona Viloyati'!C12-1 -> 0.27935014 | Q24: ='Xorazm Viloyati'!C13/'Xorazm Viloyati'!C12-1 -> 0.25291569 | R24: ='Toshkent shahri'!C13/'Toshkent shahri'!C12-1 -> 0.29616212
C25: 2022 | D25: ='Ozbekiston Respublikasi'!C14/'Ozbekiston Respublikasi'!C13-1 -> 0.20983898 | E25: ='Qoraqalpogiston Respublikasi'!C14/'Qoraqalpogiston Respublikasi'!C13-1 -> 0.19447385 | F25: ='Andijon Viloyati'!C14/'Andijon Viloyati'!C13-1 -> 0.28368489 | G25: ='Buxoro Viloyati'!C14/'Buxoro Viloyati'!C13-1 -> 0.20360893 | H25: ='Jizzah Viloyati'!C14/'Jizzah Viloyati'!C13-1 -> 0.18739417 | I25: ='Qashqadaryo Viloyati'!C14/'Qashqadaryo Viloyati'!C13-1 -> 0.16883576 | J25: ='Navoiy Viloyati'!C14/'Navoiy Viloyati'!C13-1 -> 0.13744502 | K25: ='Namangan Viloyati'!C14/'Namangan Viloyati'!C13-1 -> 0.20656957 | L25: ='Samarqand Viloyati'!C14/'Samarqand Viloyati'!C13-1 -> 0.16421615 | M25: ='Surxandaryo Viloyati'!C14/'Surxandaryo Viloyati'!C13-1 -> 0.17569558 | N25: ='Sirdaryo Viloyati'!C14/'Sirdaryo Viloyati'!C13-1 -> 0.19796515 | O25: ='Toshkent Viloyati '!C14/'Toshkent Viloyati '!C13-1 -> 0.11462395 | P25: ='Fargona Viloyati'!C14/'Fargona Viloyati'!C13-1 -> 0.17059461 | Q25: ='Xorazm Viloyati'!C14/'Xorazm Viloyati'!C13-1 -> 0.25948886 | R25: ='Toshkent shahri'!C14/'Toshkent shahri'!C13-1 -> 0.23876587
... C27: 2024 | D27: ='Ozbekiston Respublikasi'!C16/'Ozbekiston Respublikasi'!C15-1 -> 0.21685267 | E27: ='Qoraqalpogiston Respublikasi'!C16/'Qoraqalpogiston Respublikasi'!C15-1 -> 0.13465441 | F27: ='Andijon Viloyati'!C16/'Andijon Viloyati'!C15-1 -> 0.15794368 | G27: ='Buxoro Viloyati'!C16/'Buxoro Viloyati'!C15-1 -> 0.15293107 | H27: ='Jizzah Viloyati'!C16/'Jizzah Viloyati'!C15-1 -> 0.12900081 | I27: ='Qashqadaryo Viloyati'!C16/'Qashqadaryo Viloyati'!C15-1 -> 0.17535877 | J27: ='Navoiy Viloyati'!C16/'Navoiy Viloyati'!C15-1 -> 0.39281805 | K27: ='Namangan Viloyati'!C16/'Namangan Viloyati'!C15-1 -> 0.17673709 | L27: ='Samarqand Viloyati'!C16/'Samarqand Viloyati'!C15-1 -> 0.2035538 | M27: ='Surxandaryo Viloyati'!C16/'Surxandaryo Viloyati'!C15-1 -> 0.14926162 | N27: ='Sirdaryo Viloyati'!C16/'Sirdaryo Viloyati'!C15-1 -> 0.15207253 | O27: ='Toshkent Viloyati '!C16/'Toshkent Viloyati '!C15-1 -> 0.21891639 | P27: ='Fargona Viloyati'!C16/'Fargona Viloyati'!C15-1 -> 0.14750415 | Q27: ='Xorazm Viloyati'!C16/'Xorazm Viloyati'!C15-1 -> 0.18257618 | R27: ='Toshkent shahri'!C16/'Toshkent shahri'!C15-1 -> 0.35864979
C28: 15 yillik o'sish | D28: ='Ozbekiston Respublikasi'!C16/'Ozbekiston Respublikasi'!C2-1 -> 16.427811 | E28: ='Qoraqalpogiston Respublikasi'!C16/'Qoraqalpogiston Respublikasi'!C2-1 -> 16.778896 | F28: ='Andijon Viloyati'!C16/'Andijon Viloyati'!C2-1 -> 17.389005 | G28: ='Buxoro Viloyati'!C16/'Buxoro Viloyati'!C2-1 -> 13.310176 | H28: ='Jizzah Viloyati'!C16/'Jizzah Viloyati'!C2-1 -> 16.847412 | I28: ='Qashqadaryo Viloyati'!C16/'Qashqadaryo Viloyati'!C2-1 -> 10.006516 | J28: ='Navoiy Viloyati'!C16/'Navoiy Viloyati'!C2-1 -> 27.475888 | K28: ='Namangan Viloyati'!C16/'Namangan Viloyati'!C2-1 -> 17.10989 | L28: ='Samarqand Viloyati'!C16/'Samarqand Viloyati'!C2-1 -> 13.542473 | M28: ='Surxandaryo Viloyati'!C16/'Surxandaryo Viloyati'!C2-1 -> 13.873994 | N28: ='Sirdaryo Viloyati'!C16/'Sirdaryo Viloyati'!C2-1 -> 14.431903 | O28: ='Toshkent Viloyati '!C16/'Toshkent Viloyati '!C2-1 -> 17.119847 | P28: ='Fargona Viloyati'!C16/'Fargona Viloyati'!C2-1 -> 14.073624 | Q28: ='Xorazm Viloyati'!C16/'Xorazm Viloyati'!C2-1 -> 15.77823 | R28: ='Toshkent shahri'!C16/'Toshkent shahri'!C2-1 -> 24.529636
C49: 2. O'ZBEKISTON RESPUBLIKASINING DEMOGRAFIK KO'RSATGICHLARINING O'SISH SURATI
C53: Yillar | D53: O'zbekiston | E53: Qoraqalpog'iston | F53: Andijon | G53: Buxoro | H53: Jizzax | I53: Qashqadaryo | J53: Navoiy | K53: Namangan | L53: Samarqand | M53: Surxondaryo | N53: Sirdaryo | O53: Toshkent vil | P53: Farg'ona | Q53: Xorazm | R53: Toshkent sh
C54: 2011 | D54: ='Ozbekiston Respublikasi'!O3/'Ozbekiston Respublikasi'!O2-1 -> 0.040069425 | E54: ='Qoraqalpogiston Respublikasi'!O3/'Qoraqalpogiston Respublikasi'!O2-1 -> 0.029963235 | F54: ='Andijon Viloyati'!O3/'Andijon Viloyati'!O2-1 -> 0.048330783 | G54: ='Buxoro Viloyati'!O3/'Buxoro Viloyati'!O2-1 -> 0.044217054 | H54: ='Jizzah Viloyati'!O3/'Jizzah Viloyati'!O2-1 -> 0.044681232 | I54: ='Qashqadaryo Viloyati'!O3/'Qashqadaryo Viloyati'!O2-1 -> 0.040824128 | J54: ='Navoiy Viloyati'!P3/'Navoiy Viloyati'!P2-1 -> 0.025129169 | K54: ='Namangan Viloyati'!O3/'Namangan Viloyati'!O2-1 -> 0.053575382 | L54: ='Samarqand Viloyati'!O3/'Samarqand Viloyati'!O2-1 -> 0.048669445 | M54: ='Surxandaryo Viloyati'!O3/'Surxandaryo Viloyati'!O2-1 -> 0.048240964 | N54: ='Sirdaryo Viloyati'!O3/'Sirdaryo Viloyati'!O2-1 -> 0.017917133 | O54: ='Toshkent Viloyati '!O3/'Toshkent Viloyati '!O2-1 -> 0.022622685 | P54: ='Fargona Viloyati'!O3/'Fargona Viloyati'!O2-1 -> 0.050282964 | Q54: ='Xorazm Viloyati'!O3/'Xorazm Viloyati'!O2-1 -> 0.02529457 | R54: ='Toshkent shahri'!O3/'Toshkent shahri'!O2-1 -> 0.027838697
C55: 2012 | D55: ='Ozbekiston Respublikasi'!O4/'Ozbekiston Respublikasi'!O3-1 -> 0.014833433 | E55: ='Qoraqalpogiston Respublikasi'!O4/'Qoraqalpogiston Respublikasi'!O3-1 -> 0.0070795407 | F55: ='Andijon Viloyati'!O4/'Andijon Viloyati'!O3-1 -> 0.015679377 | G55: ='Buxoro Viloyati'!O4/'Buxoro Viloyati'!O3-1 -> 0.014015916 | H55: ='Jizzah Viloyati'!O4/'Jizzah Viloyati'!O3-1 -> 0.017056656 | I55: ='Qashqadaryo Viloyati'!O4/'Qashqadaryo Viloyati'!O3-1 -> 0.020162327 | J55: ='Navoiy Viloyati'!P4/'Navoiy Viloyati'!P3-1 -> 0.0093928981 | K55: ='Namangan Viloyati'!O4/'Namangan Viloyati'!O3-1 -> 0.017272536 | L55: ='Samarqand Viloyati'!O4/'Samarqand Viloyati'!O3-1 -> 0.016937752 | M55: ='Surxandaryo Viloyati'!O4/'Surxandaryo Viloyati'!O3-1 -> 0.020137005 | N55: ='Sirdaryo Viloyati'!O4/'Sirdaryo Viloyati'!O3-1 -> 0.016914191 | O55: ='Toshkent Viloyati '!O4/'Toshkent Viloyati '!O3-1 -> 0.010058993 | P55: ='Fargona Viloyati'!O4/'Fargona Viloyati'!O3-1 -> 0.01597919 | Q55: ='Xorazm Viloyati'!O4/'Xorazm Viloyati'!O3-1 -> 0.017487977 | R55: ='Toshkent shahri'!O4/'Toshkent shahri'!O3-1 -> 0.0055736991
C56: 2013 | D56: ='Ozbekiston Respublikasi'!O5/'Ozbekiston Respublikasi'!O4-1 -> 0.01482301 | E56: ='Qoraqalpogiston Respublikasi'!O5/'Qoraqalpogiston Respublikasi'!O4-1 -> 0.011224008 | F56: ='Andijon Viloyati'!O5/'Andijon Viloyati'!O4-1 -> 0.015547859 | G56: ='Buxoro Viloyati'!O5/'Buxoro Viloyati'!O4-1 -> 0.013060794 | H56: ='Jizzah Viloyati'!O5/'Jizzah Viloyati'!O4-1 -> 0.015506489 | I56: ='Qashqadaryo Viloyati'!O5/'Qashqadaryo Viloyati'!O4-1 -> 0.019259846 | J56: ='Navoiy Viloyati'!P5/'Navoiy Viloyati'!P4-1 -> 0.0081706764 | K56: ='Namangan Viloyati'!O5/'Namangan Viloyati'!O4-1 -> 0.015739899 | L56: ='Samarqand Viloyati'!O5/'Samarqand Viloyati'!O4-1 -> 0.016445193 | M56: ='Surxandaryo Viloyati'!O5/'Surxandaryo Viloyati'!O4-1 -> 0.018793096 | N56: ='Sirdaryo Viloyati'!O5/'Sirdaryo Viloyati'!O4-1 -> 0.015010142 | O56: ='Toshkent Viloyati '!O5/'Toshkent Viloyati '!O4-1 -> 0.0092474729 | P56: ='Fargona Viloyati'!O5/'Fargona Viloyati'!O4-1 -> 0.014904901 | Q56: ='Xorazm Viloyati'!O5/'Xorazm Viloyati'!O4-1 -> 0.015161746 | R56: ='Toshkent shahri'!O5/'Toshkent shahri'!O4-1 -> 0.0136838
C57: 2014 | D57: ='Ozbekiston Respublikasi'!O6/'Ozbekiston Respublikasi'!O5-1 -> 0.01664694 | E57: ='Qoraqalpogiston Respublikasi'!O6/'Qoraqalpogiston Respublikasi'!O5-1 -> 0.014429256 | F57: ='Andijon Viloyati'!O6/'Andijon Viloyati'!O5-1 -> 0.01781309 | G57: ='Buxoro Viloyati'!O6/'Buxoro Viloyati'!O5-1 -> 0.015436203 | H57: ='Jizzah Viloyati'!O6/'Jizzah Viloyati'!O5-1 -> 0.018091286 | I57: ='Qashqadaryo Viloyati'!O6/'Qashqadaryo Viloyati'!O5-1 -> 0.022604457 | J57: ='Navoiy Viloyati'!P6/'Navoiy Viloyati'!P5-1 -> 0.014295362 | K57: ='Namangan Viloyati'!O6/'Namangan Viloyati'!O5-1 -> 0.018465043 | L57: ='Samarqand Viloyati'!O6/'Samarqand Viloyati'!O5-1 -> 0.019136916 | M57: ='Surxandaryo Viloyati'!O6/'Surxandaryo Viloyati'!O5-1 -> 0.021100593 | N57: ='Sirdaryo Viloyati'!O6/'Sirdaryo Viloyati'!O5-1 -> 0.017585931 | O57: ='Toshkent Viloyati '!O6/'Toshkent Viloyati '!O5-1 -> 0.011203027 | P57: ='Fargona Viloyati'!O6/'Fargona Viloyati'!O5-1 -> 0.017058594 | Q57: ='Xorazm Viloyati'!O6/'Xorazm Viloyati'!O5-1 -> 0.018321442 | R57: ='Toshkent shahri'!O6/'Toshkent shahri'!O5-1 -> 0.0051262335
C58: 2015 | D58: ='Ozbekiston Respublikasi'!O7/'Ozbekiston Respublikasi'!O6-1 -> 0.017371314 | E58: ='Qoraqalpogiston Respublikasi'!O7/'Qoraqalpogiston Respublikasi'!O6-1 -> 0.015318169 | F58: ='Andijon Viloyati'!O7/'Andijon Viloyati'!O6-1 -> 0.018463732 | G58: ='Buxoro Viloyati'!O7/'Buxoro Viloyati'!O6-1 -> 0.016511045 | H58: ='Jizzah Viloyati'!O7/'Jizzah Viloyati'!O6-1 -> 0.018992501 | I58: ='Qashqadaryo Viloyati'!O7/'Qashqadaryo Viloyati'!O6-1 -> 0.021966636 | J58: ='Navoiy Viloyati'!P7/'Navoiy Viloyati'!P6-1 -> 0.013428032 | K58: ='Namangan Viloyati'!O7/'Namangan Viloyati'!O6-1 -> 0.020007188 | L58: ='Samarqand Viloyati'!O7/'Samarqand Viloyati'!O6-1 -> 0.020083585 | M58: ='Surxandaryo Viloyati'!O7/'Surxandaryo Viloyati'!O6-1 -> 0.021660963 | N58: ='Sirdaryo Viloyati'!O7/'Sirdaryo Viloyati'!O6-1 -> 0.017412935 | O58: ='Toshkent Viloyati '!O7/'Toshkent Viloyati '!O6-1 -> 0.011885983 | P58: ='Fargona Viloyati'!O7/'Fargona Viloyati'!O6-1 -> 0.017244943 | Q58: ='Xorazm Viloyati'!O7/'Xorazm Viloyati'!O6-1 -> 0.018704352 | R58: ='Toshkent shahri'!O7/'Toshkent shahri'!O6-1 -> 0.0078201369
C59: 2016 | D59: ='Ozbekiston Respublikasi'!O8/'Ozbekiston Respublikasi'!O7-1 -> 0.017819325 | E59: ='Qoraqalpogiston Respublikasi'!O8/'Qoraqalpogiston Respublikasi'!O7-1 -> 0.015881118 | F59: ='Andijon Viloyati'!O8/'Andijon Viloyati'!O7-1 -> 0.018618976 | G59: ='Buxoro Viloyati'!O8/'Buxoro Viloyati'!O7-1 -> 0.016690938 | H59: ='Jizzah Viloyati'!O8/'Jizzah Viloyati'!O7-1 -> 0.020798336 | I59: ='Qashqadaryo Viloyati'!O8/'Qashqadaryo Viloyati'!O7-1 -> 0.022542161 | J59: ='Navoiy Viloyati'!P8/'Navoiy Viloyati'!P7-1 -> 0.01609724 | K59: ='Namangan Viloyati'!O8/'Namangan Viloyati'!O7-1 -> 0.019262391 | L59: ='Samarqand Viloyati'!O8/'Samarqand Viloyati'!O7-1 -> 0.019659725 | M59: ='Surxandaryo Viloyati'!O8/'Surxandaryo Viloyati'!O7-1 -> 0.022558623 | N59: ='Sirdaryo Viloyati'!O8/'Sirdaryo Viloyati'!O7-1 -> 0.017372282 | O59: ='Toshkent Viloyati '!O8/'Toshkent Viloyati '!O7-1 -> 0.012979009 | P59: ='Fargona Viloyati'!O8/'Fargona Viloyati'!O7-1 -> 0.017533165 | Q59: ='Xorazm Viloyati'!O8/'Xorazm Viloyati'!O7-1 -> 0.018244346 | R59: ='Toshkent shahri'!O8/'Toshkent shahri'!O7-1 -> 0.0092354405
C60: 2017 | D60: ='Ozbekiston Respublikasi'!O9/'Ozbekiston Respublikasi'!O8-1 -> 0.017266661 | E60: ='Qoraqalpogiston Respublikasi'!O9/'Qoraqalpogiston Respublikasi'!O8-1 -> 0.014739546 | F60: ='Andijon Viloyati'!O9/'Andijon Viloyati'!O8-1 -> 0.017866346 | G60: ='Buxoro Viloyati'!O9/'Buxoro Viloyati'!O8-1 -> 0.015590569 | H60: ='Jizzah Viloyati'!O9/'Jizzah Viloyati'!O8-1 -> 0.019512577 | I60: ='Qashqadaryo Viloyati'!O9/'Qashqadaryo Viloyati'!O8-1 -> 0.020888419 | J60: ='Navoiy Viloyati'!P9/'Navoiy Viloyati'!P8-1 -> 0.016057765 | K60: ='Namangan Viloyati'!O9/'Namangan Viloyati'!O8-1 -> 0.018821541 | L60: ='Samarqand Viloyati'!O9/'Samarqand Viloyati'!O8-1 -> 0.018917939 | M60: ='Surxandaryo Viloyati'!O9/'Surxandaryo Viloyati'!O8-1 -> 0.021065727 | N60: ='Sirdaryo Viloyati'!O9/'Sirdaryo Viloyati'!O8-1 -> 0.015810777 | O60: ='Toshkent Viloyati '!O9/'Toshkent Viloyati '!O8-1 -> 0.012597974 | P60: ='Fargona Viloyati'!O9/'Fargona Viloyati'!O8-1 -> 0.016974296 | Q60: ='Xorazm Viloyati'!O9/'Xorazm Viloyati'!O8-1 -> 0.01705879 | R60: ='Toshkent shahri'!O9/'Toshkent shahri'!O8-1 -> 0.012911583
C61: 2018 | D61: ='Ozbekiston Respublikasi'!O10/'Ozbekiston Respublikasi'!O9-1 -> 0.016693389 | E61: ='Qoraqalpogiston Respublikasi'!O10/'Qoraqalpogiston Respublikasi'!O9-1 -> 0.013645117 | F61: ='Andijon Viloyati'!O10/'Andijon Viloyati'!O9-1 -> 0.016607595 | G61: ='Buxoro Viloyati'!O10/'Buxoro Viloyati'!O9-1 -> 0.01448332 | H61: ='Jizzah Viloyati'!O10/'Jizzah Viloyati'!O9-1 -> 0.018447348 | I61: ='Qashqadaryo Viloyati'!O10/'Qashqadaryo Viloyati'!O9-1 -> 0.019295519 | J61: ='Navoiy Viloyati'!P10/'Navoiy Viloyati'!P9-1 -> 0.016122189 | K61: ='Namangan Viloyati'!O10/'Namangan Viloyati'!O9-1 -> 0.017795204 | L61: ='Samarqand Viloyati'!O10/'Samarqand Viloyati'!O9-1 -> 0.018731002 | M61: ='Surxandaryo Viloyati'!O10/'Surxandaryo Viloyati'!O9-1 -> 0.021077854 | N61: ='Sirdaryo Viloyati'!O10/'Sirdaryo Viloyati'!O9-1 -> 0.015938239 | O61: ='Toshkent Viloyati '!O10/'Toshkent Viloyati '!O9-1 -> 0.011274874 | P61: ='Fargona Viloyati'!O10/'Fargona Viloyati'!O9-1 -> 0.015540844 | Q61: ='Xorazm Viloyati'!O10/'Xorazm Viloyati'!O9-1 -> 0.015928407 | R61: ='Toshkent shahri'!O10/'Toshkent shahri'!O9-1 -> 0.016830989
C62: 2019 | D62: ='Ozbekiston Respublikasi'!O11/'Ozbekiston Respublikasi'!O10-1 -> 0.018336207 | E62: ='Qoraqalpogiston Respublikasi'!O11/'Qoraqalpogiston Respublikasi'!O10-1 -> 0.014926993 | F62: ='Andijon Viloyati'!O11/'Andijon Viloyati'!O10-1 -> 0.018328519 | G62: ='Buxoro Viloyati'!O11/'Buxoro Viloyati'!O10-1 -> 0.013153673 | H62: ='Jizzah Viloyati'!O11/'Jizzah Viloyati'!O10-1 -> 0.020679245 | I62: ='Qashqadaryo Viloyati'!O11/'Qashqadaryo Viloyati'!O10-1 -> 0.020550121 | J62: ='Navoiy Viloyati'!P11/'Navoiy Viloyati'!P10-1 -> 0.022442589 | K62: ='Namangan Viloyati'!O11/'Namangan Viloyati'!O10-1 -> 0.019743666 | L62: ='Samarqand Viloyati'!O11/'Samarqand Viloyati'!O10-1 -> 0.021182226 | M62: ='Surxandaryo Viloyati'!O11/'Surxandaryo Viloyati'!O10-1 -> 0.022154164 | N62: ='Sirdaryo Viloyati'!O11/'Sirdaryo Viloyati'!O10-1 -> 0.017158966 | O62: ='Toshkent Viloyati '!O11/'Toshkent Viloyati '!O10-1 -> 0.013036488 | P62: ='Fargona Viloyati'!O11/'Fargona Viloyati'!O10-1 -> 0.017429976 | Q62: ='Xorazm Viloyati'!O11/'Xorazm Viloyati'!O10-1 -> 0.01700831 | R62: ='Toshkent shahri'!O11/'Toshkent shahri'!O10-1 -> 0.018256319
C63: 2020 | D63: ='Ozbekiston Respublikasi'!O12/'Ozbekiston Respublikasi'!O11-1 -> 0.019536618 | E63: ='Qoraqalpogiston Respublikasi'!O12/'Qoraqalpogiston Respublikasi'!O11-1 -> 0.015242272 | F63: ='Andijon Viloyati'!O12/'Andijon Viloyati'!O11-1 -> 0.019824579 | G63: ='Buxoro Viloyati'!O12/'Buxoro Viloyati'!O11-1 -> 0.015357821 | H63: ='Jizzah Viloyati'!O12/'Jizzah Viloyati'!O11-1 -> 0.021960958 | I63: ='Qashqadaryo Viloyati'!O12/'Qashqadaryo Viloyati'!O11-1 -> 0.020945504 | J63: ='Navoiy Viloyati'!P12/'Navoiy Viloyati'!P11-1 -> 0.017968351 | K63: ='Namangan Viloyati'!O12/'Namangan Viloyati'!O11-1 -> 0.021032366 | L63: ='Samarqand Viloyati'!O12/'Samarqand Viloyati'!O11-1 -> 0.020663876 | M63: ='Surxandaryo Viloyati'!O12/'Surxandaryo Viloyati'!O11-1 -> 0.023035916 | N63: ='Sirdaryo Viloyati'!O12/'Sirdaryo Viloyati'!O11-1 -> 0.019761417 | O63: ='Toshkent Viloyati '!O12/'Toshkent Viloyati '!O11-1 -> 0.014973262 | P63: ='Fargona Viloyati'!O12/'Fargona Viloyati'!O11-1 -> 0.018651753 | Q63: ='Xorazm Viloyati'!O12/'Xorazm Viloyati'!O11-1 -> 0.016778341 | R63: ='Toshkent shahri'!O12/'Toshkent shahri'!O11-1 -> 0.024622495
C64: 2021 | D64: ='Ozbekiston Respublikasi'!O13/'Ozbekiston Respublikasi'!O12-1 -> 0.019280228 | E64: ='Qoraqalpogiston Respublikasi'!O13/'Qoraqalpogiston Respublikasi'!O12-1 -> 0.013380393 | F64: ='Andijon Viloyati'!O13/'Andijon Viloyati'!O12-1 -> 0.019311315 | G64: ='Buxoro Viloyati'!O13/'Buxoro Viloyati'!O12-1 -> 0.012058839 | H64: ='Jizzah Viloyati'!O13/'Jizzah Viloyati'!O12-1 -> 0.020548441 | I64: ='Qashqadaryo Viloyati'!O13/'Qashqadaryo Viloyati'!O12-1 -> 0.016766248 | J64: ='Navoiy Viloyati'!P13/'Navoiy Viloyati'!P12-1 -> 0.016547989 | K64: ='Namangan Viloyati'!O13/'Namangan Viloyati'!O12-1 -> 0.020172193 | L64: ='Samarqand Viloyati'!O13/'Samarqand Viloyati'!O12-1 -> 0.018130706 | M64: ='Surxandaryo Viloyati'!O13/'Surxandaryo Viloyati'!O12-1 -> 0.019664524 | N64: ='Sirdaryo Viloyati'!O13/'Sirdaryo Viloyati'!O12-1 -> 0.017251566 | O64: ='Toshkent Viloyati '!O13/'Toshkent Viloyati '!O12-1 -> 0.011557157 | P64: ='Fargona Viloyati'!O13/'Fargona Viloyati'!O12-1 -> 0.018123667 | Q64: ='Xorazm Viloyati'!O13/'Xorazm Viloyati'!O12-1 -> 0.014358425 | R64: ='Toshkent shahri'!O13/'Toshkent shahri'!O12-1 -> 0.04771163
C65: 2022 | D65: ='Ozbekiston Respublikasi'!O14/'Ozbekiston Respublikasi'!O13-1 -> 0.020614082 | E65: ='Qoraqalpogiston Respublikasi'!O14/'Qoraqalpogiston Respublikasi'!O13-1 -> 0.012891823 | F65: ='Andijon Viloyati'!O14/'Andijon Viloyati'!O13-1 -> 0.020513786 | G65: ='Buxoro Viloyati'!O14/'Buxoro Viloyati'!O13-1 -> 0.015253454 | H65: ='Jizzah Viloyati'!O14/'Jizzah Viloyati'!O13-1 -> 0.023325062 | I65: ='Qashqadaryo Viloyati'!O14/'Qashqadaryo Viloyati'!O13-1 -> 0.021856449 | J65: ='Navoiy Viloyati'!P14/'Navoiy Viloyati'!P13-1 -> 0.020027624 | K65: ='Namangan Viloyati'!O14/'Namangan Viloyati'!O13-1 -> 0.022179599 | L65: ='Samarqand Viloyati'!O14/'Samarqand Viloyati'!O13-1 -> 0.021176888 | M65: ='Surxandaryo Viloyati'!O14/'Surxandaryo Viloyati'!O13-1 -> 0.023276634 | N65: ='Sirdaryo Viloyati'!O14/'Sirdaryo Viloyati'!O13-1 -> 0.020559879 | O65: ='Toshkent Viloyati '!O14/'Toshkent Viloyati '!O13-1 -> -0.011559528 | P65: ='Fargona Viloyati'!O14/'Fargona Viloyati'!O13-1 -> 0.02 | Q65: ='Xorazm Viloyati'!O14/'Xorazm Viloyati'!O13-1 -> 0.01632071 | R65: ='Toshkent shahri'!O14/'Toshkent shahri'!O13-1 -> 0.061683492
... C67: 2024 | D67: ='Ozbekiston Respublikasi'!O16/'Ozbekiston Respublikasi'!O15-1 -> 0.021510122 | E67: ='Qoraqalpogiston Respublikasi'!O16/'Qoraqalpogiston Respublikasi'!O15-1 -> 0.013409574 | F67: ='Andijon Viloyati'!O16/'Andijon Viloyati'!O15-1 -> 0.021578836 | G67: ='Buxoro Viloyati'!O16/'Buxoro Viloyati'!O15-1 -> 0.017067224 | H67: ='Jizzah Viloyati'!O16/'Jizzah Viloyati'!O15-1 -> 0.02161979 | I67: ='Qashqadaryo Viloyati'!O16/'Qashqadaryo Viloyati'!O15-1 -> 0.022485139 | J67: ='Navoiy Viloyati'!P16/'Navoiy Viloyati'!P15-1 -> 0.018758882 | K67: ='Namangan Viloyati'!O16/'Namangan Viloyati'!O15-1 -> 0.022885738 | L67: ='Samarqand Viloyati'!O16/'Samarqand Viloyati'!O15-1 -> 0.021927056 | M67: ='Surxandaryo Viloyati'!O16/'Surxandaryo Viloyati'!O15-1 -> 0.025155888 | N67: ='Sirdaryo Viloyati'!O16/'Sirdaryo Viloyati'!O15-1 -> 0.019406647 | O67: ='Toshkent Viloyati '!O16/'Toshkent Viloyati '!O15-1 -> 0.019509588 | P67: ='Fargona Viloyati'!O16/'Fargona Viloyati'!O15-1 -> 0.021426955 | Q67: ='Xorazm Viloyati'!O16/'Xorazm Viloyati'!O15-1 -> 0.019151218 | R67: ='Toshkent shahri'!O16/'Toshkent shahri'!O15-1 -> 0.028548234
C68: 15 yillik o'sish | D68: ='Ozbekiston Respublikasi'!O16/'Ozbekiston Respublikasi'!O2-1 -> 0.31421286 | E68: ='Qoraqalpogiston Respublikasi'!O16/'Qoraqalpogiston Respublikasi'!O2-1 -> 0.22714461 | F68: ='Andijon Viloyati'!O16/'Andijon Viloyati'!O2-1 -> 0.33160723 | G68: ='Buxoro Viloyati'!O16/'Buxoro Viloyati'!O2-1 -> 0.2675969 | H68: ='Jizzah Viloyati'!O16/'Jizzah Viloyati'!O2-1 -> 0.34974928 | I68: ='Qashqadaryo Viloyati'!O16/'Qashqadaryo Viloyati'!O2-1 -> 0.3610336 | J68: ='Navoiy Viloyati'!P16/'Navoiy Viloyati'!P2-1 -> 0.26268201 | K68: ='Namangan Viloyati'!O16/'Namangan Viloyati'!O2-1 -> 0.35758247 | L68: ='Samarqand Viloyati'!O16/'Samarqand Viloyati'!O2-1 -> 0.34931068 | M68: ='Surxandaryo Viloyati'!O16/'Surxandaryo Viloyati'!O2-1 -> 0.38655422 | N68: ='Sirdaryo Viloyati'!O16/'Sirdaryo Viloyati'!O2-1 -> 0.2793953 | O68: ='Toshkent Viloyati '!O16/'Toshkent Viloyati '!O2-1 -> 0.18016938 | P68: ='Fargona Viloyati'!O16/'Fargona Viloyati'!O2-1 -> 0.32098484 | Q68: ='Xorazm Viloyati'!O16/'Xorazm Viloyati'!O2-1 -> 0.27792008 | R68: ='Toshkent shahri'!O16/'Toshkent shahri'!O2-1 -> 0.36096317
C92: 3

Sheet Ozbekiston Respublikasi
A1: Zip Code | B1: Years | C1: Yalpi ichki (hududiy) mahsulot hajmi (yillik) | D1: Asosiy kapitalga investitsiyalar hajmi (yillik) | E1: Aholi jon boshiga asosiy kapitalga investitsiyalar hajmi (yillik) | F1: Qurilish ishlari hajmi (yillik) | G1: Tashqi savdo aylanmasi hajmi (yillik) | H1: Ulgurji savdo hajmi (yillik) | I1: Chakana savdo hajmi (yillik) | J1: Elektr energiyasi ishlab chiqarish hajmi | K1: Sanoat mahsulotlari ishlab chiqarish hajmi (yillik) | L1: Iste’mol tovarlari ishlab chiqarish hajmi (yillik) | M1: Qishloq xo‘jaligi mahsulotlari umumiy hajmi (yillik) | N1: Atmosferaga chiqarilgan ifloslantiruvchi moddalar | O1: Doimiy aholi soni (1000 birlikda) | P1: Tug‘ilganlar soni (jami) | Q1: Tug‘ilganlar soni (qiz bolalar) | R1: Tug‘ilganlar soni (o‘g‘il bolalar) | S1: Vafot etganlar soni (jami) | T1: Mehnat resurslari soni (1000 birlikda) | U1: Iqtisodiy faol aholi soni (1000 birlikda) | V1: Iqtisodiy nofaol aholi soni (1000 birlikda) | W1: Iqtisodiyotda bandlar soni (ming kishi) | X1: Bandlik darajasi (Foiz %) | Y1: Ishsizlar soni (ming kishi) | Z1: Aholi jon boshiga umumiy daromadlar hajmi (hududlar kesimida) (ming so'm) | AA1: Faoliyat ko‘rsatayotgan korxona va tashkilotlar soni (yillik) (birlik) | AB1: Ro‘yxatga olingan jinoyatlar soni (hududlar bo‘yicha) (birlik)
B2: 31/12/2010 | C2: 88102.4 | D2: 16463.7 | E2: 583.2 | F2: 8245.8 | G2: 22199.2 | H2: 11774100 | I2: 21872.8 | J2: 51976.3 | K2: 38119 | L2: 13683.8 | M2: 30856.7 | N2: 729 | O2: 28001.4 | P2: 634810 | Q2: 305902 | R2: 328908 | S2: 138411 | T2: 16726 | U2: 12286.6 | V2: 4439.4 | W2: 11628.4 | X2: 66.9 | Y2: 658.2 | Z2: 2192.8 | AA2: 200951 | AB2: 90050
B3: 31/12/2011 | C3: 115627.8 | D3: 19500 | E3: 664.6 | F3: 9504.8 | G3: 26365.9 | H3: 15476700 | I3: 28539 | J3: 52806.2 | K3: 47587.1 | L3: 18336.4 | M3: 45285.9 | N3: 788.2 | O3: 29123.4 | P3: 622835 | Q3: 299395 | R3: 323440 | S3: 143253 | T3: 17286.4 | U3: 12541.5 | V3: 4744.9 | W3: 11919.1 | X3: 66.2 | Y3: 622.4 | Z3: 2928.9 | AA3: 214084 | AB3: 90617
B4: 31/12/2012 | C4: 142333 | D4: 24455.3 | E4: 821.4 | F4: 11753.9 | G4: 26416.1 | H4: 18018800 | I4: 36946.4 | J4: 52999.6 | K4: 57552.5 | L4: 21527.8 | M4: 55750 | N4: 817.6 | O4: 29555.4 | P4: 625106 | Q4: 300408 | R4: 324698 | S4: 145988 | T4: 17564.3 | U4: 12850.1 | V4: 4714.2 | W4: 12223.8 | X4: 66.6 | Y4: 626.3 | Z4: 3501.8 | AA4: 228736 | AB4: 90660
B5: 31/12/2013 | C5: 173201.5 | D5: 30490.1 | E5: 1008.2 | F5: 15219.3 | G5: 28269.6 | H5: 22001677 | I5: 46863 | J5: 54618.6 | K5: 70634.8 | L5: 28614.1 | M5: 66435.3 | N5: 855.2 | O5: 29993.5 | P5: 679519 | Q5: 326535 | R5: 352984 | S5: 145672 | T5: 17814.1 | U5: 13163 | V5: 4651.1 | W5: 12523.3 | X5: 67.1 | Y5: 639.7 | Z5: 4175.1 | AA5: 229177 | AB5: 90152
B6: 31/12/2014 | C6: 210998.3 | D6: 37646.2 | E6: 1224 | F6: 20060.4 | G6: 27530.1 | H6: 25512624 | I6: 58136.6 | J6: 55765.6 | K6: 84011.6 | L6: 33868.5 | M6: 81794.3 | N6: 1162.1 | O6: 30492.8 | P6: 718036 | Q6: 344759 | R6: 373277 | S6: 149761 | T6: 18048 | U6: 13505.4 | V6: 4542.6 | W6: 12818.4 | X6: 67.7 | Y6: 687 | Z6: 4759.6 | AA6: 241201 | AB6: 89360
B7: 31/12/2015 | C7: 250544.6 | D7: 44810.4 | E7: 1431.7 | F7: 25423.1 | G7: 24924.3 | H7: 29156202 | I7: 71184.1 | J7: 57658.1 | K7: 97598.2 | L7: 42085.5 | M7: 99604.6 | N7: 975.1 | O7: 31022.5 | P7: 734141 | Q7: 351475 | R7: 382666 | S7: 152035 | T7: 18276.1 | U7: 13767.7 | V7: 4508.4 | W7: 13058.3 | X7: 68.2 | Y7: 709.4 | Z7: 5410.6 | AA7: 246687 | AB7: 87946
B8: 31/12/2016 | C8: 290213.4 | D8: 51232 | E8: 1608.6 | F8: 29413.9 | G8: 24232.2 | H8: 35396463 | I8: 88071.6 | J8: 59100.5 | K8: 111869.4 | L8: 48253.8 | M8: 115599.2 | N8: 1008.2 | O8: 31575.3 | P8: 726170 | Q8: 348453 | R8: 377717 | S8: 154791 | T8: 18488.9 | U8: 14022.4 | V8: 4466.5 | W8: 13298.4 | X8: 68.7 | Y8: 724 | Z8: 6215.9 | AA8: 257758 | AB8: 87412
B9: 31/12/2017 | C9: 369612.8 | D9: 72155.2 | E9: 2227.8 | F9: 34698 | G9: 26566.1 | H9: 38799693 | I9: 105229.9 | J9: 60820.1 | K9: 148816 | L9: 59690.4 | M9: 148199.3 | N9: 853.5 | O9: 32120.5 | P9: 715519 | Q9: 343105 | R9: 372414 | S9: 160723 | T9: 18666.3 | U9: 14357.3 | V9: 4309 | W9: 13520.3 | X9: 69.2 | Y9: 837 | Z9: 7698.6 | AA9: 268428 | AB9: 73692
B10: 31/12/2018 | C10: 494814.8 | D10: 124231.3 | E10: 3769.6 | F10: 51129.3 | G10: 33430 | H10: 57481980 | I10: 133195.2 | J10: 62896.6 | K10: 235340.7 | L10: 83512.6 | M10: 187425.6 | N10: 883.7 | O10: 32656.7 | P10: 768520 | Q10: 365216 | R10: 403304 | S10: 154913 | T10: 18829.6 | U10: 14641.7 | V10: 4187.9 | W10: 13273.1 | X10: 67.4 | Y10: 1368.6 | Z10: 9517.4 | AA10: 285531 | AB10: 49011
B11: 31/12/2019 | C11: 620083.2 | D11: 195927.3 | E11: 5834.6 | F11: 71156.5 | G11: 41751 | H11: 86538274 | I11: 166094.4 | J11: 63531.6 | K11: 322535.8 | L11: 110321 | M11: 216283.1 | N11: 952.8 | O11: 33255.5 | P11: 814960 | Q11: 391698 | R11: 423262 | S11: 154570 | T11: 18949 | U11: 14876.4 | V11: 4072.6 | W11: 13541.1 | X11: 68.1 | Y11: 1335.3 | Z11: 11357.5 | AA11: 323517 | AB11: 46089
B12: 31/12/2020 | C12: 705076.5 | D12: 210195.1 | E12: 6140.3 | F12: 88130.3 | G12: 36256.1 | H12: 129000000 | I12: 199518.8 | J12: 66500.7 | K12: 368740.2 | L12: 129348.6 | M12: 250250.6 | N12: 924.4 | O12: 33905.2 | P12: 841817 | Q12: 405466 | R12: 436351 | S12: 175625 | T12: 19158.2 | U12: 14797.4 | V12: 4360.8 | W12: 13236.4 | X12: 66 | Y12: 1561 | Z12: 12595.9 | AA12: 398133 | AB12: 62081
B13: 31/12/2021 | C13: 861170.8 | D13: 239552.6 | E13: 6861 | F13: 107492.7 | G13: 42170.5 | H13: 183000000 | I13: 252056.6 | J13: 71364.6 | K13: 456056.1 | L13: 155159.1 | M13: 303415.5 | N13: 908.7 | O13: 34558.9 | P13: 905211 | Q13: 436727 | R13: 468484 | S13: 174541 | T13: 19334.9 | U13: 14980.7 | V13: 4354.2 | W13: 13538.9 | X13: 67 | Y13: 1441.8 | Z13: 15421.7 | AA13: 475197 | AB13: 111082
B14: 31/12/2022 | C14: 1041878 | D14: 266240 | E14: 7468.6 | F14: 130790.9 | G14: 50500.3 | H14: 258000000 | I14: 270687.2 | J14: 74269.3 | K14: 553265 | L14: 145011.7 | M14: 345191.7 | N14: 873.6 | O14: 35271.3 | P14: 932217 | Q14: 449849 | R14: 482368 | S14: 172068 | T14: 19517.5 | U14: 15038.9 | V14: 4478.6 | W14: 13706.2 | X14: 67.2 | Y14: 1332.7 | Z14: 18373.9 | AA14: 528929 | AB14: 105215
B15: 31/12/2023 | C15: 1261806 | D15: 356071.4 | E15: 9778.8 | F15: 222935.8 | G15: 63528.6 | H15: 386000000 | I15: 330448.1 | J15: 78005.4 | K15: 658991.7 | M15: 405418 | N15: 763.2 | O15: 36024.9 | P15: 961962 | Q15: 463717 | R15: 498245 | S15: 172757 | T15: 19739.6 | U15: 15038.3 | V15: 4701.3 | W15: 14014.2 | X15: 67.9 | Y15: 1024.1 | Z15: 20764.5 | AA15: 592371 | AB15: 104096
B16: 31/12/2024 | C16: 1535432 | D16: 507490.2 | E16: 0 | F16: 259654.3 | G16: 67238.4 | H16: 457000000 | I16: 410068.1 | J16: 82739.7 | K16: 880198.5 | M16: 439948 | N16: 866.7 | O16: 36799.8 | P16: 926422 | Q16: 446870 | R16: 479552 | S16: 174413 | T16: 20085.2 | U16: 15097.9 | V16: 4987.3 | W16: 14261.9 | X16: 68.3 | Y16: 836 | Z16: 24111.9 | AA16: 485024 | AB16: 132298

Sheet Qoraqalpogiston Respublikasi
A1: Zip Code | B1: Years | C1: Yalpi ichki (hududiy) mahsulot hajmi (yillik) | D1: Asosiy kapitalga investitsiyalar hajmi (yillik) | E1: Aholi jon boshiga asosiy kapitalga investitsiyalar hajmi (yillik) | F1: Qurilish ishlari hajmi (yillik) | G1: Tashqi savdo aylanmasi hajmi (yillik) | H1: Ulgurji savdo hajmi (yillik) | I1: Chakana savdo hajmi (yillik) | J1: Elektr energiyasi ishlab chiqarish hajmi | K1: Sanoat mahsulotlari ishlab chiqarish hajmi (yillik) | L1: Iste’mol tovarlari ishlab chiqarish hajmi (yillik) | M1: Qishloq xo‘jaligi mahsulotlari umumiy hajmi (yillik) | N1: Atmosferaga chiqarilgan ifloslantiruvchi moddalar | O1: Doimiy aholi soni | P1: Tug‘ilganlar soni (jami) | Q1: Tug‘ilganlar soni (qiz bolalar) | R1: Tug‘ilganlar soni (o‘g‘il bolalar) | S1: Vafot etganlar soni (jami) | T1: Mehnat resurslari soni(ming kishi birlikda) | U1: Iqtisodiy faol aholi soni ming kishi | V1: Iqtisodiy nofaol aholi soni | W1: Iqtisodiyotda bandlar soni (ming kishi) | X1: Bandlik darajasi (Foiz %) | Y1: Ishsizlar soni (ming kishi) | Z1: Aholi jon boshiga umumiy daromadlar hajmi (hududlar kesimida) (ming so'm) | AA1: Faoliyat ko‘rsatayotgan korxona va tashkilotlar soni (yillik) (birlik) | AB1: Ro‘yxatga olingan jinoyatlar soni (hududlar bo‘yicha) (birlik)
A2: 230100 | B2: 31/12/2010 | C2: 2604.2 | D2: 496.4 | E2: 302.6 | F2: 237.1 | G2: 126.3 | H2: 292400 | I2: 711.3 | J2: 3100.2 | K2: 697.2 | L2: 250.7 | M2: 990.4 | N2: 29.2 | O2: 1632 | P2: 37942 | Q2: 18406 | R2: 19536 | S2: 8342 | T2: 945.5 | U2: 627.4 | V2: 318.1 | W2: 580.8 | X2: 57.3 | Y2: 46.6 | Z2: 1498.9 | AA2: 9835 | AB2: 3182
A3: 230100 | B3: 31/12/2011 | C3: 3385.3 | D3: 950.3 | E3: 563.3 | F3: 398.6 | G3: 158.3 | H3: 446300 | I3: 897.3 | J3: 3306.3 | K3: 897.8 | L3: 334.4 | M3: 1282.1 | N3: 23.5 | O3: 1680.9 | P3: 35840 | Q3: 17369 | R3: 18471 | S3: 8184 | T3: 973.8 | U3: 631.7 | V3: 342.1 | W3: 590 | X3: 57 | Y3: 41.7 | Z3: 1972.2 | AA3: 10370 | AB3: 3189
A4: 230100 | B4: 31/12/2012 | C4: 4236.2 | D4: 1242.1 | E4: 729.7 | F4: 537.2 | G4: 240.3 | H4: 474600 | I4: 1155.2 | J4: 3100.5 | K4: 1034.2 | L4: 391.4 | M4: 1812.2 | N4: 19.5 | O4: 1692.8 | P4: 38207 | Q4: 18474 | R4: 19733 | S4: 8208 | T4: 983.5 | U4: 641.5 | V4: 342 | W4: 600.2 | X4: 57.4 | Y4: 41.3 | Z4: 2414.4 | AA4: 11300 | AB4: 3425
A5: 230100 | B5: 31/12/2013 | C5: 5519.4 | D5: 2415 | E5: 1400.7 | F5: 720.8 | G5: 233.8 | H5: 463035 | I5: 1568.3 | J5: 3213.8 | K5: 1368.8 | L5: 579 | M5: 2071.4 | N5: 25.8 | O5: 1711.8 | P5: 39100 | Q5: 19004 | R5: 20096 | S5: 8134 | T5: 996.6 | U5: 650.8 | V5: 345.8 | W5: 610.5 | X5: 57.7 | Y5: 40.3 | Z5: 2856.6 | AA5: 11274 | AB5: 3164
A6: 230100 | B6: 31/12/2014 | C6: 6887.2 | D6: 3990.6 | E6: 2280.6 | F6: 1053.5 | G6: 316.9 | H6: 562131.2 | I6: 1977.8 | J6: 3466.6 | K6: 1717.2 | L6: 699.2 | M6: 2558.7 | N6: 26.7 | O6: 1736.5 | P6: 40883 | Q6: 19563 | R6: 21320 | S6: 8157 | T6: 1011.9 | U6: 656.7 | V6: 355.2 | W6: 621 | X6: 57.9 | Y6: 35.7 | Z6: 3317.1 | AA6: 11306 | AB6: 3107
A7: 230100 | B7: 31/12/2015 | C7: 8339.9 | D7: 6021.2 | E7: 3388.2 | F7: 1219.3 | G7: 286.1 | H7: 683698.5 | I7: 2397.7 | J7: 3451.3 | K7: 2387.6 | L7: 1051.1 | M7: 3332.2 | N7: 32.8 | O7: 1763.1 | P7: 41345 | Q7: 19958 | R7: 21387 | S7: 8094 | T7: 1026.6 | U7: 665.4 | V7: 361.2 | W7: 630 | X7: 58.1 | Y7: 35.4 | Z7: 3908 | AA7: 12234 | AB7: 3042
A8: 230100 | B8: 31/12/2016 | C8: 10524.5 | D8: 3778.3 | E8: 2094.1 | F8: 1171.8 | G8: 628.5 | H8: 709733 | I8: 2950.4 | J8: 3632.7 | K8: 4265.7 | L8: 1088.8 | M8: 3929.8 | N8: 30.6 | O8: 1791.1 | P8: 39427 | Q8: 18991 | R8: 20436 | S8: 8396 | T8: 1042.2 | U8: 675.1 | V8: 367.1 | W8: 638.6 | X8: 58.1 | Y8: 36.5 | Z8: 4372 | AA8: 12552 | AB8: 3456
A9: 230100 | B9: 31/12/2017 | C9: 13755.6 | D9: 2822 | E9: 1528.8 | F9: 1398.8 | G9: 641.1 | H9: 800620.6 | I9: 3527.8 | J9: 3446.1 | K9: 6773.3 | L9: 1209.2 | M9: 4801.3 | N9: 37.7 | O9: 1817.5 | P9: 37754 | Q9: 18367 | R9: 19387 | S9: 8661 | T9: 1054.6 | U9: 688.8 | V9: 365.8 | W9: 647.2 | X9: 58.3 | Y9: 41.6 | Z9: 5510.5 | AA9: 12946 | AB9: 2861
A10: 230100 | B10: 31/12/2018 | C10: 19372.3 | D10: 6757.8 | E10: 3641.1 | F10: 2182.7 | G10: 742 | H10: 1231805 | I10: 4496.8 | J10: 3855.9 | K10: 10911.9 | L10: 1815 | M10: 6562.9 | N10: 34 | O10: 1842.3 | P10: 40108 | Q10: 19627 | R10: 20481 | S10: 8602 | T10: 1064.8 | U10: 779.5 | V10: 285.3 | W10: 705.2 | X10: 62.9 | Y10: 74.3 | Z10: 7117.6 | AA10: 13742 | AB10: 1968
A11: 230100 | B11: 31/12/2019 | C11: 23896.7 | D11: 8750.6 | E11: 4644.4 | F11: 3315.4 | G11: 700 | H11: 1607347 | I11: 5705.8 | J11: 3786.1 | K11: 12736.1 | L11: 2377.6 | M11: 8208.1 | N11: 37.2 | O11: 1869.8 | P11: 41137 | Q11: 19892 | R11: 21245 | S11: 8461 | T11: 1063 | U11: 782.2 | V11: 280.8 | W11: 711.3 | X11: 62.9 | Y11: 70.9 | Z11: 8530.5 | AA11: 15590 | AB11: 1870
A12: 230100 | B12: 31/12/2020 | C12: 26136.6 | D12: 7089.8 | E12: 3710 | F12: 3992.5 | G12: 539 | H12: 2113942 | I12: 6861.8 | J12: 4392.4 | K12: 13981.3 | L12: 2804.2 | M12: 9751.6 | N12: 28.9 | O12: 1898.3 | P12: 39286 | Q12: 19064 | R12: 20222 | S12: 9164 | T12: 1074.7 | U12: 790 | V12: 284.7 | W12: 707.4 | X12: 62 | Y12: 82.6 | Z12: 9815.9 | AA12: 18404 | AB12: 2092
A13: 230100 | B13: 31/12/2021 | C13: 30697.7 | D13: 8110.7 | E13: 4189.2 | F13: 4480.6 | G13: 649.2 | H13: 2402092 | I13: 7582.5 | J13: 5233.9 | K13: 16630.4 | L13: 2945.6 | M13: 11511.8 | N13: 31.4 | O13: 1923.7 | P13: 40272 | Q13: 19338 | R13: 20934 | S13: 8756 | T13: 1066.1 | U13: 781.5 | V13: 284.6 | W13: 702.6 | X13: 61.1 | Y13: 78.9 | Z13: 11731.8 | AA13: 21968 | AB13: 3306
A14: 230100 | B14: 31/12/2022 | C14: 36667.6 | D14: 10254 | E14: 5225.5 | F14: 5272.4 | G14: 599.3 | H14: 3626827 | I14: 9557.9 | J14: 5373.9 | K14: 17624.7 | L14: 2393.3 | M14: 13348.2 | N14: 21.1 | O14: 1948.5 | P14: 42835 | Q14: 20807 | R14: 22028 | S14: 9585 | T14: 1067.6 | U14: 786.1 | V14: 281.5 | W14: 714.2 | X14: 61.6 | Y14: 71.9 | Z14: 13779.1 | AA14: 23721 | AB14: 3367
A15: 230100 | B15: 31/12/2023 | C15: 40805.2 | D15: 12959.2 | E15: 6514.1 | F15: 7995.6 | G15: 535.2 | H15: 5743073 | I15: 11392.6 | J15: 5152.1 | K15: 17791.1 | M15: 15212.1 | N15: 9.8 | O15: 1976.2 | P15: 44021 | Q15: 21267 | R15: 22754 | S15: 10092 | T15: 1072.6 | U15: 791.8 | V15: 280.8 | W15: 735.5 | X15: 62.9 | Y15: 56.3 | Z15: 15037.5 | AA15: 26692 | AB15: 3554
A16: 230100 | B16: 31/12/2024 | C16: 46299.8 | D16: 20567.7 | E16: 10201.22 | F16: 8505.9 | G16: 653 | H16: 6757340 | I16: 14263.8 | J16: 5079 | K16: 24323.5 | M16: 16339.7 | N16: 10.5 | O16: 2002.7 | P16: 41641 | Q16: 19969 | R16: 21672 | S16: 10184 | T16: 1098.6 | U16: 805.8 | V16: 292.8 | W16: 759.4 | X16: 64.3 | Y16: 46.4 | Z16: 16858 | AA16: 25928 | AB16: 4673

Sheet Andijon Viloyati
A1: Zip Code | B1: Years | C1: Yalpi ichki (hududiy) mahsulot hajmi (yillik) | D1: Asosiy kapitalga investitsiyalar hajmi (yillik) | E1: Aholi jon boshiga asosiy kapitalga investitsiyalar hajmi (yillik) | F1: Qurilish ishlari hajmi (yillik) | G1: Tashqi savdo aylanmasi hajmi (yillik) | H1: Ulgurji savdo hajmi (yillik) | I1: Chakana savdo hajmi (yillik) | J1: Elektr energiyasi ishlab chiqarish hajmi | K1: Sanoat mahsulotlari ishlab chiqarish hajmi (yillik) | L1: Iste’mol tovarlari ishlab chiqarish hajmi (yillik) | M1: Qishloq xo‘jaligi mahsulotlari umumiy hajmi (yillik) | N1: Atmosferaga chiqarilgan ifloslantiruvchi moddalar | O1: Doimiy aholi soni | P1: Tug‘ilganlar soni (jami) | Q1: Tug‘ilganlar soni (qiz bolalar) | R1: Tug‘ilganlar soni (o‘g‘il bolalar) | S1: Vafot etganlar soni (jami) | T1: Mehnat resurslari soni | U1: Iqtisodiy faol aholi soni | V1: Iqtisodiy nofaol aholi soni | W1: Iqtisodiyotda bandlar soni (ming kishi) | X1: Bandlik darajasi (Foiz %) | Y1: Ishsizlar soni (ming kishi) | Z1: Aholi jon boshiga umumiy daromadlar hajmi (hududlar kesimida) (ming so'm) | AA1: Faoliyat ko‘rsatayotgan korxona va tashkilotlar soni (yillik) (birlik) | AB1: Ro‘yxatga olingan jinoyatlar soni (hududlar bo‘yicha) (birlik)
A2: 170100 | B2: 31/12/2010 | C2: 5058.8 | D2: 726.2 | E2: 282.3 | F2: 345.3 | G2: 2097.6 | H2: 428100 | I2: 1704.2 | J2: 774 | K2: 4701.4 | L2: 3266.9 | M2: 2841.1 | N2: 8.7 | O2: 2549.1 | P2: 59953 | Q2: 28895 | R2: 31058 | S2: 12862 | T2: 1561.2 | U2: 1180.2 | V2: 381 | W2: 1112 | X2: 69.3 | Y2: 68.2 | Z2: 1838.1 | AA2: 18070 | AB2: 5716
A3: 170100 | B3: 31/12/2011 | C3: 6892.3 | D3: 1037.2 | E3: 385.1 | F3: 534.4 | G3: 2387.8 | H3: 727000 | I3: 2230.8 | J3: 751.8 | K3: 5727.3 | L3: 3887.6 | M3: 4264.9 | N3: 13.6 | O3: 2672.3 | P3: 56662 | Q3: 27156 | R3: 29506 | S3: 13933 | T3: 1597.4 | U3: 1209.3 | V3: 388.1 | W3: 1144.7 | X3: 68.6 | Y3: 64.6 | Z3: 2523.9 | AA3: 20041 | AB3: 5710
A4: 170100 | B4: 31/12/2012 | C4: 8487.3 | D4: 1379.9 | E4: 504.5 | F4: 672.9 | G4: 2899.7 | H4: 738100 | I4: 2835 | J4: 632 | K4: 6934.9 | L4: 4843 | M4: 5283.6 | N4: 12.2 | O4: 2714.2 | P4: 58277 | Q4: 28051 | R4: 30226 | S4: 14160 | T4: 1606.8 | U4: 1242.6 | V4: 364.2 | W4: 1176.3 | X4: 69 | Y4: 66.3 | Z4: 2945.8 | AA4: 21815 | AB4: 5683
A5: 170100 | B5: 31/12/2013 | C5: 11159.9 | D5: 1462.3 | E5: 525.8 | F5: 862.7 | G5: 2912 | H5: 831688.1 | I5: 3671.1 | J5: 569.8 | K5: 9278.6 | L5: 6717.3 | M5: 6575.4 | N5: 14.4 | O5: 2756.4 | P5: 64239 | Q5: 30857 | R5: 33382 | S5: 14188 | T5: 1641.7 | U5: 1279.2 | V5: 362.5 | W5: 1210.7 | X5: 69.9 | Y5: 68.5 | Z5: 3754.5 | AA5: 22606 | AB5: 5676
A6: 170100 | B6: 31/12/2014 | C6: 13331.4 | D6: 1645 | E6: 581 | F6: 1131.8 | G6: 2453.4 | H6: 993355.5 | I6: 4563.8 | J6: 438.5 | K6: 10463.2 | L6: 7329.6 | M6: 7992.4 | N6: 6.6 | O6: 2805.5 | P6: 67905 | Q6: 32689 | R6: 35216 | S6: 14519 | T6: 1667.9 | U6: 1318.7 | V6: 349.2 | W6: 1245 | X6: 70.8 | Y6: 73.7 | Z6: 4267.6 | AA6: 23991 | AB6: 5643
A7: 170100 | B7: 31/12/2015 | C7: 15705.4 | D7: 1956.5 | E7: 678.4 | F7: 1341.9 | G7: 1564.6 | H7: 1132757 | I7: 5564.3 | J7: 674.1 | K7: 9744.6 | L7: 7159.7 | M7: 9796.6 | N7: 18.5 | O7: 2857.3 | P7: 69562 | Q7: 33424 | R7: 36138 | S7: 14860 | T7: 1691.2 | U7: 1347.3 | V7: 343.9 | W7: 1271.7 | X7: 71.5 | Y7: 75.6 | Z7: 4835 | AA7: 24835 | AB7: 5640
A8: 170100 | B8: 31/12/2016 | C8: 18376.6 | D8: 2188.5 | E8: 745.3 | F8: 1578 | G8: 1102.7 | H8: 1149951 | I8: 6777.8 | J8: 647.9 | K8: 7965.7 | L8: 5313.5 | M8: 11873.4 | N8: 36.7 | O8: 2910.5 | P8: 68784 | Q8: 33025 | R8: 35759 | S8: 15084 | T8: 1709.1 | U8: 1375.2 | V8: 333.9 | W8: 1297.7 | X8: 72.3 | Y8: 77.5 | Z8: 5637.3 | AA8: 26048 | AB8: 5678
A9: 170100 | B9: 31/12/2017 | C9: 22904.2 | D9: 2986 | E9: 999.6 | F9: 1782.9 | G9: 1596.9 | H9: 1243051 | I9: 8124.9 | J9: 847.4 | K9: 13269.8 | L9: 9853.1 | M9: 15290.9 | N9: 15.8 | O9: 2962.5 | P9: 67368 | Q9: 32418 | R9: 34950 | S9: 16122 | T9: 1722.2 | U9: 1404.1 | V9: 318.1 | W9: 1319.2 | X9: 73 | Y9: 84.9 | Z9: 7149 | AA9: 26278 | AB9: 4507
A10: 170100 | B10: 31/12/2018 | C10: 31623.2 | D10: 4711.9 | E10: 1550.3 | F10: 2819.5 | G10: 2176.4 | H10: 2288336 | I10: 10367.9 | J10: 769.5 | K10: 27454.7 | L10: 21385.4 | M10: 19606.3 | N10: 15.9 | O10: 3011.7 | P10: 72387 | Q10: 32424 | R10: 39963 | S10: 15377 | T10: 1733.3 | U10: 1401.6 | V10: 331.7 | W10: 1266.8 | X10: 69.6 | Y10: 134.8 | Z10: 8785.8 | AA10: 24644 | AB10: 3494
A11: 170100 | B11: 31/12/2019 | C11: 39663.7 | D11: 7452.1 | E11: 2406 | F11: 3539.1 | G11: 2532.8 | H11: 2436754 | I11: 12704.3 | J11: 623.6 | K11: 33122.3 | L11: 26179.4 | M11: 23686.7 | N11: 14.3 | O11: 3066.9 | P11: 77603 | Q11: 37488 | R11: 40115 | S11: 14656 | T11: 1741.7 | U11: 1413.9 | V11: 327.8 | W11: 1284.5 | X11: 70.1 | Y11: 129.4 | Z11: 10390.4 | AA11: 27391 | AB11: 3361
A12: 170100 | B12: 31/12/2020 | C12: 44097.9 | D12: 9622.6 | E12: 3047.2 | F12: 4673 | G12: 2795.4 | H12: 3719178 | I12: 14810.1 | J12: 372.6 | K12: 36376.5 | L12: 27490.4 | M12: 26096.1 | N12: 11.5 | O12: 3127.7 | P12: 81425 | Q12: 39616 | R12: 41809 | S12: 15797 | T12: 1754.8 | U12: 1376.5 | V12: 378.3 | W12: 1225.9 | X12: 66.5 | Y12: 150.6 | Z12: 11237.6 | AA12: 30740 | AB12: 4618
A13: 170100 | B13: 31/12/2021 | C13: 50817.3 | D13: 11176.6 | E13: 3470.1 | F13: 5657.8 | G13: 3165.4 | H13: 4283897 | I13: 15376.3 | J13: 489.2 | K13: 35935.3 | L13: 25823.9 | M13: 30413 | N13: 4.9 | O13: 3188.1 | P13: 84664 | Q13: 41083 | R13: 43581 | S13: 16409 | T13: 1745.3 | U13: 1403.1 | V13: 342.2 | W13: 1264.3 | X13: 68.2 | Y13: 138.8 | Z13: 13449.7 | AA13: 36726 | AB13: 6930
A14: 170100 | B14: 31/12/2022 | C14: 65233.4 | D14: 14339.8 | E14: 4361.1 | F14: 6864.1 | G14: 4282.5 | H14: 6313985 | I14: 19046.9 | J14: 791.4 | K14: 54352.5 | L14: 36563.5 | M14: 35587.4 | N14: 17.3 | O14: 3253.5 | P14: 86506 | Q14: 41748 | R14: 44758 | S14: 15426 | T14: 1780.8 | U14: 1427.3 | V14: 353.5 | W14: 1296.8 | X14: 69.5 | Y14: 130.5 | Z14: 16443.6 | AA14: 40474 | AB14: 7231
A15: 170100 | B15: 31/12/2023 | C15: 80337.5 | D15: 18639.1 | E15: 5549.8 | F15: 10931 | G15: 5047.9 | H15: 11517876 | I15: 22770.8 | J15: 658.1 | K15: 73767.1 | M15: 41035.7 | N15: 10.5 | O15: 3322.7 | P15: 89400 | Q15: 43369 | R15: 46031 | S15: 15877 | T15: 1799.6 | U15: 1429.7 | V15: 369.9 | W15: 1329 | X15: 70.6 | Y15: 100.7 | Z15: 19236.1 | AA15: 44658 | AB15: 7487
A16: 170100 | B16: 31/12/2024 | C16: 93026.3 | D16: 28668 | E16: 8363.618 | F16: 12782.8 | G16: 4201.4 | H16: 13235128 | I16: 28630.5 | J16: 820 | K16: 90626.6 | M16: 44074.7 | N16: 32.6 | O16: 3394.4 | P16: 86305 | Q16: 41991 | R16: 44314 | S16: 17815 | T16: 1807.4 | U16: 1415.5 | V16: 391.9 | W16: 1338.6 | X16: 70.2 | Y16: 76.9 | Z16: 21926.3 | AA16: 29717 | AB16: 8743

Sheet Buxoro Viloyati
A1: Zip Code | B1: Years | C1: Yalpi ichki (hududiy) mahsulot hajmi (yillik) | D1: Asosiy kapitalga investitsiyalar hajmi (yillik) | E1: Aholi jon boshiga asosiy kapitalga investitsiyalar hajmi (yillik) | F1: Qurilish ishlari hajmi (yillik) | G1: Tashqi savdo aylanmasi hajmi (yillik) | H1: Ulgurji savdo hajmi (yillik) | I1: Chakana savdo hajmi (yillik) | J1: Elektr energiyasi ishlab chiqarish hajmi | K1: Sanoat mahsulotlari ishlab chiqarish hajmi (yillik) | L1: Iste’mol tovarlari ishlab chiqarish hajmi (yillik) | M1: Qishloq xo‘jaligi mahsulotlari umumiy hajmi (yillik) | N1: Atmosferaga chiqarilgan ifloslantiruvchi moddalar | O1: Doimiy aholi soni | P1: Tug‘ilganlar soni (jami) | Q1: Tug‘ilganlar soni (qiz bolalar) | R1: Tug‘ilganlar soni (o‘g‘il bolalar) | S1: Vafot etganlar soni (jami) | T1: Mehnat resurslari soni | U1: Iqtisodiy faol aholi soni | V1: Iqtisodiy nofaol aholi soni | W1: Iqtisodiyotda bandlar soni (ming kishi) | X1: Bandlik darajasi (Foiz %) | Y1: Ishsizlar soni (ming kishi) | Z1: Aholi jon boshiga umumiy daromadlar hajmi (hududlar kesimida) (ming so'm) | AA1: Faoliyat ko‘rsatayotgan korxona va tashkilotlar soni (yillik) (birlik) | AB1: Ro‘yxatga olingan jinoyatlar soni (hududlar bo‘yicha) (birlik)
A2: 200100 | B2: 31/12/2010 | C2: 5131.6 | D2: 2147.2 | E2: 1321.5 | F2: 580 | G2: 762.6 | H2: 444800 | I2: 1290.2 | J2: 5.7 | K2: 1674.8 | L2: 764.1 | M2: 2426.3 | N2: 75.5 | O2: 1612.5 | P2: 34597 | Q2: 16577 | R2: 18020 | S2: 7383 | T2: 987.6 | U2: 810 | V2: 177.6 | W2: 768.1 | X2: 74.5 | Y2: 41.9 | Z2: 2524.4 | AA2: 12360 | AB2: 4349
A3: 200100 | B3: 31/12/2011 | C3: 6777.3 | D3: 2101.8 | E3: 1239.5 | F3: 793.5 | G3: 860.1 | H3: 661400 | I3: 1726.5 | J3: 7.6 | K3: 2202.6 | L3: 977.2 | M3: 3749.3 | N3: 71.7 | O3: 1683.8 | P3: 32948 | Q3: 15934 | R3: 17014 | S3: 7521 | T3: 1008.3 | U3: 825 | V3: 183.3 | W3: 784.7 | X3: 73.5 | Y3: 40.3 | Z3: 3505.6 | AA3: 13055 | AB3: 4199
A4: 200100 | B4: 31/12/2012 | C4: 7949.5 | D4: 2405.8 | E4: 1399.9 | F4: 978.5 | G4: 913.8 | H4: 773400 | I4: 2259.7 | J4: 6.9 | K4: 2457.8 | L4: 1082 | M4: 4489.6 | N4: 61.7 | O4: 1707.4 | P4: 34257 | Q4: 16467 | R4: 17790 | S4: 7486 | T4: 1025.7 | U4: 844.5 | V4: 181.2 | W4: 804.4 | X4: 74.1 | Y4: 40.1 | Z4: 4145.2 | AA4: 13057 | AB4: 4251
A5: 200100 | B5: 31/12/2013 | C5: 9481.3 | D5: 2998.7 | E5: 1720.3 | F5: 1279.6 | G5: 1049.8 | H5: 890285.5 | I5: 2958.2 | J5: 6.4 | K5: 3073.9 | L5: 1331.8 | M5: 5655.5 | N5: 50.7 | O5: 1729.7 | P5: 36743 | Q5: 17583 | R5: 19160 | S5: 7662 | T5: 1035.1 | U5: 859.3 | V5: 175.8 | W5: 818.4 | X5: 74.4 | Y5: 40.9 | Z5: 4954 | AA5: 12403 | AB5: 4237
A6: 200100 | B6: 31/12/2014 | C6: 11729.4 | D6: 3583.2 | E6: 2023.4 | F6: 1648.4 | G6: 1002.8 | H6: 1185739 | I6: 3693.8 | J6: 8.9 | K6: 3972.6 | L6: 1732.7 | M6: 6856.6 | N6: 51.9 | O6: 1756.4 | P6: 38291 | Q6: 18350 | R6: 19941 | S6: 7708 | T6: 1045 | U6: 868.5 | V6: 176.5 | W6: 823.2 | X6: 74 | Y6: 45.3 | Z6: 5698.9 | AA6: 11468 | AB6: 4400
A7: 200100 | B7: 31/12/2015 | C7: 14223.4 | D7: 4075.9 | E7: 2264 | F7: 2061.7 | G7: 922.8 | H7: 1298777 | I7: 4481.8 | J7: 4.9 | K7: 5143.9 | L7: 2292 | M7: 8290.5 | N7: 55.6 | O7: 1785.4 | P7: 39352 | Q7: 18735 | R7: 20617 | S7: 7976 | T7: 1055.8 | U7: 872.4 | V7: 183.4 | W7: 824.2 | X7: 73.4 | Y7: 48.2 | Z7: 6411.6 | AA7: 12082 | AB7: 4364
A8: 200100 | B8: 31/12/2016 | C8: 16594.9 | D8: 5922.9 | E8: 3237.6 | F8: 2202.9 | G8: 715.5 | H8: 1490572 | I8: 5611.9 | J8: 6.8 | K8: 5569.6 | L8: 2635.9 | M8: 9812.2 | N8: 58.5 | O8: 1815.2 | P8: 38297 | Q8: 18444 | R8: 19853 | S8: 8013 | T8: 1065.4 | U8: 872.4 | V8: 193 | W8: 825.3 | X8: 72.9 | Y8: 47.1 | Z8: 7354.2 | AA8: 13828 | AB8: 4356
A9: 200100 | B9: 31/12/2017 | C9: 19970.6 | D9: 11613.4 | E9: 6254.2 | F9: 2543.7 | G9: 877.9 | H9: 1537773 | I9: 6578.5 | J9: 9.3 | K9: 6422.3 | L9: 3112.1 | M9: 12968.8 | N9: 63.8 | O9: 1843.5 | P9: 37228 | Q9: 17813 | R9: 19415 | S9: 8336 | T9: 1073.1 | U9: 874.6 | V9: 198.5 | W9: 826.5 | X9: 72.5 | Y9: 48.1 | Z9: 9325.3 | AA9: 14809 | AB9: 4204
A10: 200100 | B10: 31/12/2018 | C10: 25773.6 | D10: 9610.9 | E10: 5112.4 | F10: 3581.2 | G10: 911.3 | H10: 1809226 | I10: 8375 | J10: 6.5 | K10: 8601.2 | L10: 3661.3 | M10: 17064.6 | N10: 74.8 | O10: 1870.2 | P10: 40338 | Q10: 18950 | R10: 21388 | S10: 7978 | T10: 1077.8 | U10: 887.7 | V10: 190.1 | W10: 810.1 | X10: 70.7 | Y10: 77.6 | Z10: 11849.4 | AA10: 15625 | AB10: 2972
A11: 200100 | B11: 31/12/2019 | C11: 33081.4 | D11: 10366.6 | E11: 5429.3 | F11: 4368.1 | G11: 1259.4 | H11: 3112334 | I11: 10309.2 | J11: 5.5 | K11: 14798.2 | L11: 5311.1 | M11: 19182.1 | N11: 69.1 | O11: 1894.8 | P11: 41141 | Q11: 19607 | R11: 21534 | S11: 8335 | T11: 1081 | U11: 875.4 | V11: 205.6 | W11: 797.1 | X11: 69.3 | Y11: 78.3 | Z11: 13703.9 | AA11: 18115 | AB11: 2720
A12: 200100 | B12: 31/12/2020 | C12: 36621.6 | D12: 12183.9 | E12: 6295 | F12: 5659.8 | G12: 831.2 | H12: 4587610 | I12: 12072.8 | J12: 6.2 | K12: 17574.4 | L12: 6701.9 | M12: 23876 | N12: 37.1 | O12: 1923.9 | P12: 41555 | Q12: 20044 | R12: 21511 | S12: 10055 | T12: 1067.1 | U12: 881.9 | V12: 185.2 | W12: 788 | X12: 68.3 | Y12: 93.9 | Z12: 15338.7 | AA12: 23459 | AB12: 3570
A13: 200100 | B13: 31/12/2021 | C13: 44628.2 | D13: 20528.3 | E13: 10462.9 | F13: 7401.1 | G13: 1180.9 | H13: 6991634 | I13: 12747.1 | J13: 7.4 | K13: 20772.1 | L13: 8570.2 | M13: 28529.3 | N13: 44.8 | O13: 1947.1 | P13: 43173 | Q13: 21111 | R13: 22062 | S13: 9129 | T13: 1072.3 | U13: 862.2 | V13: 210.1 | W13: 777.3 | X13: 67.2 | Y13: 84.9 | Z13: 18910 | AA13: 28233 | AB13: 5267
A14: 200100 | B14: 31/12/2022 | C14: 53714.9 | D14: 21638.3 | E14: 10855.5 | F14: 8448.7 | G14: 1224.8 | H14: 13450873 | I14: 15522 | J14: 1578.3 | K14: 27202.4 | L14: 4899.6 | M14: 32867.5 | N14: 35.6 | O14: 1976.8 | P14: 45058 | Q14: 21711 | R14: 23347 | S14: 9069 | T14: 1074.7 | U14: 856.4 | V14: 218.3 | W14: 780.6 | X14: 67.2 | Y14: 75.8 | Z14: 22320.7 | AA14: 31160 | AB14: 5175
A15: 200100 | B15: 31/12/2023 | C15: 63693.4 | D15: 31030.5 | E15: 15309.4 | F15: 14524.8 | G15: 1212.3 | H15: 16024848 | I15: 18167.1 | J15: 2029.3 | K15: 31860.4 | M15: 37174.5 | N15: 30.7 | O15: 2009.7 | P15: 46617 | Q15: 22342 | R15: 24275 | S15: 8758 | T15: 1089.2 | U15: 858.8 | V15: 230.4 | W15: 803.2 | X15: 68.7 | Y15: 55.6 | Z15: 24267.7 | AA15: 33686 | AB15: 5339
A16: 200100 | B16: 31/12/2024 | C16: 73434.1 | D16: 51663.9 | E16: 25073.48 | F16: 16648.9 | G16: 1324.5 | H16: 17819676 | I16: 22420.5 | J16: 2582 | K16: 42243.7 | M16: 40307.9 | N16: 35.4 | O16: 2044 | P16: 46067 | Q16: 22221 | R16: 23846 | S16: 9588 | T16: 1085.3 | U16: 841.8 | V16: 243.5 | W16: 796.7 | X16: 67.7 | Y16: 45.1 | Z16: 27508 | AA16: 31203 | AB16: 7489

Sheet Jizzah Viloyati
